# 예외처리 try, catch, reject, async, await, tryCatch

## try catch

- try...catch는 동기적인 상황에서 에러를 처리하는 기법

```js
try {
  asasdfas;
} catch (e) {
  log(e, '핸들링함');
}
```

- 특정 함수에서 throw를 사용할 수도 있다.

```js
function a() {
  throw 'error!';
}

try {
  a();
} catch (e) {
  log(e);
}
```

```js
try {
  log( JSON.parse('{') );
} catch (e) {
  log(e);
}
```

- 위와 같은 코드도 throw를 통해 에러가 발생하고 catch를 이용하여 에러가 처리된다.

- finally는 항상 실행된다.

```js
try {
  log( JSON.parse('{') );
} catch (e) {
  log(e);
} finally {
  log('finally');
}
```

----

```js
function test() {
  try {
    return JSON.parse('{}');
  } catch (e) {
    log(e);
  } finally {
    log('finally');
  }
}

log(test(), 'log!');
```

- 함수에 try...catch..finally가 설정되어 있고 해당 함수를 호출했을 때
- 해당 함수가 정상적으로 실행되어도 finally는 실행된다.

- 하지만 다음과 같이 try 부분이 실패한다면

```js
function test() {
  try {
    return JSON.parse('{');
  } catch (e) {
    log(e);
  } finally {
    log('finally');
  }
}

log(test(), 'log!');
```

- 결과가 return 되지 않고 바로 catch가 실행된다.

## Promise.reject .catch

- 비동기 상황의 에러를 처리하기 위한 메소드
- 비동기 에러는 try catch 만으로는 잡을 수 없다.

```js
function test() {
  try {
    setTimeout(function() {
      JSON.parse('{');
    }, 10);
  } catch (e) {
    log(e);
  } finally {
    log('finally');
  }
}
```

- 위의 코드를 실행해보면 catch가 실행되지 않는다.
- 즉 비동기 상황에서 catch가 제대로 동작하지 않는 것을 알 수 있다.
- setTimeout 함수 내에서 try catch를 사용한다면 에러를 핸들링 할 수 있다.
- 하지만 이런 방식은 try catch가 계속 중첩되고, 안쪽의 에러를 바깥으로 전달할 수 있는 방법이 없다.

```js
function test() {
  return new Promise((resolve, reject) => {
    setTimeout(function() {
      try {
        resolve(JSON.parse('{'));
      } catch (e) {
        reject(e);
      }
    }, 10);
  });
}

test()
  .then(function(obj) {
    log('정상 동작함', obj);
  })
  .catch(function(e) {
    log('에러남', e);
  });
```

- test 함수는 Promise를 return 한다.
- try 구문이 정상적으로 실행되면 resolve를 return하고 then에서 받아서 출력한다.
- 오류가 발생할 경우 reject를 return하고 catch에서 받아서 처리한다.
- 이렇게 하면 error를 외부에서 받아서 처리할 수 있다.

```js
test()
  .then(function(obj) {
    log('정상 동작함', obj);
  }, function(e) {
    log('에러남', e);
  });
```

- 위와 같이 then 함수에 함수를 2개 전달하여 resolve, reject 경우를 각각 처리할 수도 있다.

----

```js
function test() {
  return new Promise((resolve, reject) => {
    setTimeout(function() {
      try {
        resolve(JSON.parse('{'));
      } catch (e) {
        reject(e);
      }
    }, 10);
  });
}

try {
  log(test());
} catch(e) {
  log(e, 'error!');
}
```

- 위와 같이 try catch가 포함된 함수를 try catch에 감싸서 실행하면 try catch가 정상적으로 동작하지 않는다.
- 이때는 함수 호출을 다시 함수로 감싸고 바깥 함수에 async 키워드를 사용할 수 있다.

```js
function test() {
  return new Promise((resolve, reject) => {
    setTimeout(function() {
      try {
        resolve(JSON.parse('{'));
      } catch (e) {
        reject(e);
      }
    }, 10);
  });
}

async function a() {
  try {
    log(await test());
  } catch(e) {
    log(e, 'error!');
  }
};

a();
```

- 위 예제는 async, await 만으로 처리됐다기보다는 test 함수에서 reject를 return했고 await test()가 reject가 되어 catch가 호출된 것이다.
- 결국 async await도 Promise와 동일한 동작을 수행한 것이다.
- test 함수에서 reject를 return하지 않았다면 a 함수의 catch는 실행되지 않는다.

----

```js
function getTimes(list) {
  return list.map(function(v) {
    return [v, new Date()];
  });
}

go(getTimes([1, 2, 3]), log);
```

- 위와 같은 코드를 생각해보자.
- setTimeout을 사용하여 v만큼 지연되어 v, new Date()가 return 되도록 처리하려면 다음과 같이 작성해야 한다.

```js
function getTimes(list) {
  return map(function(v) {
    return new Promise(function(resolve) {
      setTimeout(function() {
        resolve([v, new Date()]);
      }, v);
    });
  }, list);
}

go(getTimes([1, 2, 3]), log);
```

- list.map을 사용하면 async, await를 아무리 사용하여도 잘 처리되지 않는다.

----

- 동기 비동기의 에러를 모두 catch 할 수 있는 다형적인 함수가 필요하다.

```js
function tryCatch(tryF, args, catchF) {

}
```

- 이 함수는 try 구문에서 사용할 함수 tryF, tryF에서 사용한 인자 args, 그리고 마지막으로 catch 구문에서 사용할 함수 catchF를 받는다.
- 먼저 tryCatch 함수를 사용하는 코드를 만들어보자.

```js
go(
  tryCatch(
    JSON.parse,
    ['{"a: 1}'],
    e => (log(e), '실패!')),
  log);
```

- tryF, args, catchF 함수를 각각 전달한다.
- 이 코드를 동기적으로 실행하는 tryCatch는 다음과 같다.

```js
function tryCatch(tryF, args, catchF) {
  try {
    return tryF(...args);
  } catch (e) {
    return catchF(e);
  }
}
```

- 동기적인 코드를 처리했다면 비동기 상황을 확인해보자.

```js
go(
  tryCatch(
    json => new Promise((resolve, reject) => {
      setTimeout(function() {
        try {
          resolve(JSON.parse(json));
        } catch (e) {
          reject(e);
        }
      }, 10)
    }), ['{"a: 1}'],
    e => (log(e), '실패!')),
  log
);
```

- 전달한 인자를 tryF 함수가 잘 처리할 경우에는 문제없지만, 예외가 발생하는 경우 catch문으로 처리되지 않는다.

```js
function tryCatch(tryF, args, catchF) {
  try {
    const res = tryF(...args);
    return res instanceof Promise ? res.catch(catchF) : res;
  } catch (e) {
    return catchF(e);
  }
}
```

- tryCatch 함수를 위와 같이 수정하면 비동기 예외가 발생하는 경우도 잘 처리할 수 있다.