# 예외처리 reduceB, pipeT

- pipeT는 여러 개의 함수를 실행하다가 error가 발생하면 그 이후의 함수는 실행한지 않는 함수다.
- pipeT().catch() 와 같은 형태로 error가 발생하면 catch가 실행된다.
- 기존에 pipe는 reduce로 만들었다.
- 하지만 pipeT는 중간에 멈출 수 있기 때문에 reduceB를 다시 만든다.

## reduceB

```js
const reduce = curry(function(f, coll, acc) {
  const iter = collIter(coll);
  acc = arguments.length == 2 ? iter.next().value : acc;
  for (const a of iter)
    acc = acc instanceof Promise ? acc.then(acc => f(acc, a) : f(acc, a));
  return acc;
});
```

- 기존에 만든 reduce다.
- 이 코드를 수정하여 reduceB를 만든다.

```js
const reduce = curry(function(f, coll, acc) {
  const iter = collIter(coll);
  return go(
    arguments.length == 2 ? iter.next().value : acc,
    function recur(acc) {
      var cur;
      while (!(cur = iter.next()).done) {
        acc = f(acc, cur.value);
      }
      return acc;
    });
});
```

- 일단 동기적인 코드로 reduceB를 테스트해보자.

```js
go(
  reduce((a, b) => a + b. [1, 2, 3], 10),
  log);
```

- 비동기 코드가 실행될 수 있도록 수정한다.

```js
go(
  reduceB((a, b) => Promise.resolve(a + b), [1, 2, 3], 10),
  log);
```

```js
const reduceB = curry(function(f, coll, acc) {
  const iter = collIter(coll);
  return go(
    arguments.length == 2 ? iter.next().value : acc,
    function recur(acc) {
      var cur;
      while (!(cur = iter.next()).done) {
        acc = f(acc, cur.value);
        if (acc instanceof Promise) return acc.then(recur);
      }
      return acc;
    });
});
```

- 다음의 코드들이 모두 실행될 수 있다.

```js
go(
  reduceB((a, b, brk) => {
    return b > 4 ? brk(a) : a + b;
  }, [1, 2, 3, 4, 5, 6], 10),
  log);

go(
  reduceB((a, b, brk) => b > 4 ? brk(a) : a + b, [1, 2, 3, 4, 5, 6], 10),
  log);

go(
  reduceB((a, b, brk) => b > 4 ?
    brk(Promise.resolve(a)) : a + b,
    [1, 2, 3, 4, 5, 6], 10),
  log);

go(
  reduceB((a, b, brk) => b > 4 ?
    Promise.resolve(brk(a)) : a + b,
    [1, 2, 3, 4, 5, 6], 10),
  log);

go(
  reduceB((a, b) => b > 4 ? Break.of(a) : a + b, [1, 2, 3, 4, 5, 6], 10),
  log);
```

## pipeT()

## 22:00
